[2025-02-09T05:41:14.042+0000] {local_task_job_runner.py:120} INFO - ::group::Pre task execution logs
[2025-02-09T05:41:14.071+0000] {taskinstance.py:2073} INFO - Dependencies all met for dep_context=non-requeueable deps ti=<TaskInstance: etl_MusicStreamPipeline.MusicStream_transformation_time manual__2025-02-09T05:41:11.956467+00:00 [queued]>
[2025-02-09T05:41:14.285+0000] {taskinstance.py:2073} INFO - Dependencies all met for dep_context=requeueable deps ti=<TaskInstance: etl_MusicStreamPipeline.MusicStream_transformation_time manual__2025-02-09T05:41:11.956467+00:00 [queued]>
[2025-02-09T05:41:14.286+0000] {taskinstance.py:2303} INFO - Starting attempt 1 of 1
[2025-02-09T05:41:14.296+0000] {taskinstance.py:2327} INFO - Executing <Task(PythonOperator): MusicStream_transformation_time> on 2025-02-09 05:41:11.956467+00:00
[2025-02-09T05:41:14.303+0000] {logging_mixin.py:188} WARNING - /home/***/.local/lib/python3.12/site-packages/***/task/task_runner/standard_task_runner.py:61 DeprecationWarning: This process (pid=2073) is multi-threaded, use of fork() may lead to deadlocks in the child.
[2025-02-09T05:41:14.304+0000] {standard_task_runner.py:63} INFO - Started process 2082 to run task
[2025-02-09T05:41:14.303+0000] {standard_task_runner.py:90} INFO - Running: ['***', 'tasks', 'run', 'etl_MusicStreamPipeline', 'MusicStream_transformation_time', 'manual__2025-02-09T05:41:11.956467+00:00', '--job-id', '493', '--raw', '--subdir', 'DAGS_FOLDER/etl_dag.py', '--cfg-path', '/tmp/tmp9np6xuk6']
[2025-02-09T05:41:14.305+0000] {standard_task_runner.py:91} INFO - Job 493: Subtask MusicStream_transformation_time
[2025-02-09T05:41:14.341+0000] {task_command.py:426} INFO - Running <TaskInstance: etl_MusicStreamPipeline.MusicStream_transformation_time manual__2025-02-09T05:41:11.956467+00:00 [running]> on host e5529003cf96
[2025-02-09T05:41:14.427+0000] {taskinstance.py:2644} INFO - Exporting env vars: AIRFLOW_CTX_DAG_OWNER='Le Huynh Thanh Duong' AIRFLOW_CTX_DAG_ID='etl_MusicStreamPipeline' AIRFLOW_CTX_TASK_ID='MusicStream_transformation_time' AIRFLOW_CTX_EXECUTION_DATE='2025-02-09T05:41:11.956467+00:00' AIRFLOW_CTX_TRY_NUMBER='1' AIRFLOW_CTX_DAG_RUN_ID='manual__2025-02-09T05:41:11.956467+00:00'
[2025-02-09T05:41:14.428+0000] {taskinstance.py:430} INFO - ::endgroup::
[2025-02-09T05:41:14.441+0000] {taskinstance.py:441} INFO - ::group::Post task execution logs
[2025-02-09T05:41:14.441+0000] {taskinstance.py:2890} ERROR - Task failed with exception
Traceback (most recent call last):
  File "/home/airflow/.local/lib/python3.12/site-packages/airflow/models/taskinstance.py", line 465, in _execute_task
    result = _execute_callable(context=context, **execute_callable_kwargs)
             ^^^^^^^^^^^^^^^^^^^^^^^^^^^^^^^^^^^^^^^^^^^^^^^^^^^^^^^^^^^^^
  File "/home/airflow/.local/lib/python3.12/site-packages/airflow/models/taskinstance.py", line 432, in _execute_callable
    return execute_callable(context=context, **execute_callable_kwargs)
           ^^^^^^^^^^^^^^^^^^^^^^^^^^^^^^^^^^^^^^^^^^^^^^^^^^^^^^^^^^^^
  File "/home/airflow/.local/lib/python3.12/site-packages/airflow/models/baseoperator.py", line 400, in wrapper
    return func(self, *args, **kwargs)
           ^^^^^^^^^^^^^^^^^^^^^^^^^^^
  File "/home/airflow/.local/lib/python3.12/site-packages/airflow/operators/python.py", line 235, in execute
    return_value = self.execute_callable()
                   ^^^^^^^^^^^^^^^^^^^^^^^
  File "/home/airflow/.local/lib/python3.12/site-packages/airflow/operators/python.py", line 252, in execute_callable
    return self.python_callable(*self.op_args, **self.op_kwargs)
           ^^^^^^^^^^^^^^^^^^^^^^^^^^^^^^^^^^^^^^^^^^^^^^^^^^^^^
  File "/opt/airflow/etls/transform.py", line 48, in process_time
    date_range = pd.date_range(start="2018-11-01", end="2018-12-01", freq='H', closed='left')
                 ^^^^^^^^^^^^^^^^^^^^^^^^^^^^^^^^^^^^^^^^^^^^^^^^^^^^^^^^^^^^^^^^^^^^^^^^^^^^
  File "/home/airflow/.local/lib/python3.12/site-packages/pandas/core/indexes/datetimes.py", line 1009, in date_range
    dtarr = DatetimeArray._generate_range(
            ^^^^^^^^^^^^^^^^^^^^^^^^^^^^^^
TypeError: DatetimeArray._generate_range() got an unexpected keyword argument 'closed'
[2025-02-09T05:41:14.455+0000] {taskinstance.py:1205} INFO - Marking task as FAILED. dag_id=etl_MusicStreamPipeline, task_id=MusicStream_transformation_time, execution_date=20250209T054111, start_date=20250209T054114, end_date=20250209T054114
[2025-02-09T05:41:14.467+0000] {standard_task_runner.py:110} ERROR - Failed to execute job 493 for task MusicStream_transformation_time (DatetimeArray._generate_range() got an unexpected keyword argument 'closed'; 2082)
[2025-02-09T05:41:14.477+0000] {local_task_job_runner.py:240} INFO - Task exited with return code 1
[2025-02-09T05:41:14.498+0000] {taskinstance.py:3482} INFO - 0 downstream tasks scheduled from follow-on schedule check
[2025-02-09T05:41:14.502+0000] {local_task_job_runner.py:222} INFO - ::endgroup::
